Workbook

Sheet Master Data
A1: TECHNOLOGY - SEMICONDUCTOR INDUSTRY
A3: Total Revenue
A4: Companies (in USD millions) | B4: 2024 | C4: 2023 | D4: 2022 | E4: 2021 | F4: 2020 | G4: AVG | H4: RANK
A5: NVIDIA | B5: =NVIDIA!B6 -> 60922 | C5: =NVIDIA!C6 -> 26974 | D5: =NVIDIA!D6 -> 26914 | E5: =NVIDIA!E6 -> 16675 | F5: =NVIDIA!F6 -> 10918 | G5: =AVERAGE(Table6[[#This Row],[2024]:[2020]]) -> 28480.6 | H5: 4
A6: AMD | B6: =AMD!B6 -> 25785 | C6: =AMD!C6 -> 22680 | D6: =AMD!D6 -> 23601 | E6: =AMD!E6 -> 16434 | F6: =AMD!F6 -> 9763 | G6: =AVERAGE(Table6[[#This Row],[2024]:[2020]]) -> 19652.6 | H6: 5
A7: Qualcomm | B7: =Qualcomm!B5 -> 38962 | C7: =Qualcomm!C5 -> 35820 | D7: =Qualcomm!D5 -> 44200 | E7: =Qualcomm!E5 -> 33566 | F7: =Qualcomm!F5 -> 23531 | G7: =AVERAGE(Table6[[#This Row],[2024]:[2020]]) -> 35215.8 | H7: 3
A8: ARM | B8: =ARM!B7 -> 4007 | C8: =ARM!C7 -> 3233 | D8: =ARM!D7 -> 2679 | E8: =ARM!E7 -> 2703 | F8: =ARM!F7 -> 2027 | G8: =AVERAGE(Table6[[#This Row],[2024]:[2020]]) -> 2929.8 | H8: 6
A9: TSMC | B9: =TSMC!B4*32.108 -> 92930.184 | C9: =TSMC!C4*31.15 -> 67336.955 | D9: =TSMC!D4*29.777 -> 67412.15 | E9: =TSMC!E4*28.022 -> 44482.123 | F9: =TSMC!F4*29.578 -> 39613.815 | G9: =AVERAGE(Table6[[#This Row],[2024]:[2020]]) -> 62355.046 | H9: 2
A10: Intel | B10: =Intel!B5 -> 53101 | C10: =Intel!C5 -> 54228 | D10: =Intel!D5 -> 63054 | E10: =Intel!E5 -> 79024 | F10: =Intel!F5 -> 77867 | G10: =AVERAGE(Table6[[#This Row],[2024]:[2020]]) -> 65454.8 | H10: 1
A12: Revenue YoY Growth (%)
A13: Companies | B13: 2024/23 | C13: 2023/22 | D13: 2022/21 | E13: 2021/20 | F13: CAGR | G13: RANK
A14: NVIDIA | B14: =B5/C5-1 -> 1.2585453 | C14: =C5/D5-1 -> 0.002229323 | D14: =D5/E5-1 -> 0.61403298 | E14: =E5/F5-1 -> 0.52729438 | F14: =(B5 / F5)^(1/4) - 1 -> 0.53694302 | G14: =RANK(F14,F14:F19,0) -> 1
A15: AMD | B15: =B6/C6-1 -> 0.13690476 | C15: =C6/D6-1 -> -0.03902377 | D15: =D6/E6-1 -> 0.43610807 | E15: =E6/F6-1 -> 0.68329407 | F15: =(B6 / F6)^(1/4) - 1 -> 0.27481147 | G15: =RANK(F15,F14:F19,0) -> 2
A16: Qualcomm | B16: =B7/C7-1 -> 0.08771636 | C16: =C7/D7-1 -> -0.18959276 | D16: =D7/E7-1 -> 0.31680868 | E16: =E7/F7-1 -> 0.42645871 | F16: =(B7 / F7)^(1/4) - 1 -> 0.1343582 | G16: 3
A17: ARM | B17: =B8/C8-1 -> 0.23940612 | C17: =C8/D8-1 -> 0.20679358 | D17: =D8/E8-1 -> -0.0088790233 | E17: =E8/F8-1 -> 0.33349778 | F17: =(B8 / F8)^(1/4) - 1 -> 0.18574526 | G17: 4
A18: TSMC | B18: =B9/C9-1 -> 0.38007702 | C18: =C9/D9-1 -> -0.0011154562 | D18: =D9/E9-1 -> 0.51548861 | E18: =E9/F9-1 -> 0.12289418 | F18: =(B9 / F9)^(1/4) - 1 -> 0.23759211 | G18: 5
A19: Intel | B19: =B10/C10-1 -> -0.020782622 | C19: =C10/D10-1 -> -0.13997526 | D19: =D10/E10-1 -> -0.2020905 | E19: =E10/F10-1 -> 0.014858669 | F19: =(B10 / F10)^(1/4) - 1 -> -0.091264877 | G19: 6
A21: Total Cost of Sales
A22: Companies | B22: 2024 | C22: 2023 | D22: 2022 | E22: 2021 | F22: 2020 | G22: AVG | H22: RANK
A23: NVIDIA | B23: =NVIDIA!B7 -> 16621 | C23: =NVIDIA!C7 -> 11618 | D23: =NVIDIA!D7 -> 9439 | E23: =NVIDIA!E7 -> 6279 | F23: =NVIDIA!F7 -> 4150 | G23: =AVERAGE(B23:F23) -> 9621.4 | H23: =_xlfn.RANK.EQ(G23,G23:G28,1) -> 3
A24: AMD | B24: =AMD!B7 -> 13060 | C24: =AMD!C7 -> 12220 | D24: =AMD!D7 -> 12998 | E24: =AMD!E7 -> 8505 | F24: =AMD!F7 -> 5416 | G24: =AVERAGE(B24:F24) -> 10439.8 | H24: =_xlfn.RANK.EQ(G24,G23:G28,1) -> 4
A25: Qualcomm | B25: =Qualcomm!B6 -> 17060 | C25: =Qualcomm!C6 -> 15869 | D25: =Qualcomm!D6 -> 18635 | E25: =Qualcomm!E6 -> 14262 | F25: =Qualcomm!F6 -> 9255 | G25: =AVERAGE(B25:F25) -> 15016.2 | H25: =_xlfn.RANK.EQ(G25,G23:G28,1) -> 5
A26: ARM | B26: =ARM!B9 -> -121 | C26: =ARM!C9 -> -154 | D26: =ARM!D9 -> -106 | E26: =ARM!E9 -> -131 | F26: =ARM!F9 -> -145 | G26: =AVERAGE(B26:F26) -> -131.4 | H26: =_xlfn.RANK.EQ(G26,G23:G28,1) -> 1
A27: TSMC | B27: =TSMC!B5*32.108 -> 40777.16 | C27: =TSMC!C5*31.15 -> 30732.59 | D27: =TSMC!D5*29.777 -> 27260.844 | E27: =TSMC!E5*28.022 -> 21518.094 | F27: =TSMC!F5*29.578 -> 18577.942 | G27: =AVERAGE(B27:F27) -> 27773.326 | H27: =_xlfn.RANK.EQ(G27,G23:G28,1) -> 6
A28: Intel | B28: =Intel!B6 -> 34877 | C28: =Intel!C6 -> 31282 | D28: =Intel!D6 -> 34608 | E28: =Intel!E6 -> 35209 | F28: =Intel!F6 -> 34255 | G28: =Intel!G6 -> 0 | H28: =_xlfn.RANK.EQ(G28,G23:G28,1) -> 2
A30: Cost of Sales to Total Sales
A31: Companies | B31: 2024 | C31: 2023 | D31: 2022 | E31: 2021 | F31: 2020 | G31: AVG | H31: RANK
A32: NVIDIA | B32: =B23/B5 -> 0.27282427 | C32: =C23/C5 -> 0.43071106 | D32: =D23/D5 -> 0.35070967 | E32: =E23/E5 -> 0.37655172 | F32: =F23/F5 -> 0.38010625 | G32: =AVERAGE(B32:F32) -> 0.36218059 | H32: =_xlfn.RANK.EQ(G32,G32:G37,1) -> 2
A33: AMD | B33: =B24/B6 -> 0.50649602 | C33: =C24/C6 -> 0.53880071 | D33: =D24/D6 -> 0.55073938 | E33: =E24/E6 -> 0.51752464 | F33: =F24/F6 -> 0.55474752 | G33: =AVERAGE(B33:F33) -> 0.53366165 | H33: =_xlfn.RANK.EQ(G33,G32:G37,1) -> 6
A34: Qualcomm | B34: =B25/B7 -> 0.43786253 | C34: =C25/C7 -> 0.44302066 | D34: =D25/D7 -> 0.42160633 | E34: =E25/E7 -> 0.42489424 | F34: =F25/F7 -> 0.39331095 | G34: =AVERAGE(B34:F34) -> 0.42413894 | H34: =_xlfn.RANK.EQ(G34,G32:G37,1) -> 3
A35: ARM | B35: =B26/B8 -> -0.030197155 | C35: =C26/C8 -> -0.047633777 | D35: =D26/D8 -> -0.039567003 | E35: =E26/E8 -> -0.048464669 | F35: =F26/F8 -> -0.071534287 | G35: =AVERAGE(B35:F35) -> -0.047479378 | H35: =_xlfn.RANK.EQ(G35,G32:G37,1) -> 1
A36: TSMC | B36: =B27/B9 -> 0.43879349 | C36: =C27/C9 -> 0.45640006 | D36: =D27/D9 -> 0.40439065 | E36: =E27/E9 -> 0.48374701 | F36: =F27/F9 -> 0.46897633 | G36: =AVERAGE(B36:F36) -> 0.45046151 | H36: =_xlfn.RANK.EQ(G36,G32:G37,1) -> 4
A37: Intel | B37: =B28/B10 -> 0.65680496 | C37: =C28/C10 -> 0.57686066 | D37: =D28/D10 -> 0.54886288 | E37: =E28/E10 -> 0.44554819 | F37: =F28/F10 -> 0.43991678 | G37: =AVERAGE(B37:F37) -> 0.53359869 | H37: =_xlfn.RANK.EQ(G37,G32:G37,1) -> 5
A39: Operating Expenses to Total Sales
A40: Companies | B40: 2024 | C40: 2023 | D40: 2022 | E40: 2021 | F40: 2020 | G40: AVG | H40: RANK
A41: NVIDIA | B41: =B168/B5 -> 0.1859591 | C41: =C168/C5 -> 0.41269371 | D41: =D168/D5 -> 0.27621312 | E41: =E168/E5 -> 0.35166417 | F41: =F168/F5 -> 0.3592233 | G41: =AVERAGE(B41:F41) -> 0.31715068 | H41: =_xlfn.RANK.EQ(G41,G41:G46,1) -> 2
A42: AMD | B42: =B169/B6 -> 0.41981772 | C42: =C169/C6 -> 0.23536155 | D42: =D169/D6 -> 0.39570357 | E42: =E169/E6 -> 0.26049653 | F42: =F169/F6 -> 0.30502919 | G42: =AVERAGE(B42:F42) -> 0.32328171 | H42: =_xlfn.RANK.EQ(G42,G41:G46,1) -> 3
A43: Qualcomm | B43: =B170/B7 -> 0.34284688 | C43: =C170/C7 -> 0.36599665 | D43: =D170/D7 -> 0.28339367 | E43: =E170/E7 -> 0.3306024 | F43: =F170/F7 -> 0.40125792 | G43: =AVERAGE(B43:F43) -> 0.3448195 | H43: =_xlfn.RANK.EQ(G43,G41:G46,1) -> 4
A44: ARM | B44: =B171/B8 -> 0.76241577 | C44: =C171/C8 -> 0.91803279 | D44: =D171/D8 -> 0.70996641 | E44: =E171/E8 -> 0.71735109 | F44: =F171/F8 -> 0.81055747 | G44: =AVERAGE(B44:F44) -> 0.78366471 | H44: =_xlfn.RANK.EQ(G44,G41:G46,1) -> 6
A45: TSMC | B45: =B172/B9 -> 0.0027181696 | C45: =C172/C9 -> 0.0033651655 | D45: =D172/D9 -> 0.0030409948 | E45: =E172/E9 -> 0.0033384198 | F45: =F172/F9 -> 0.0031630379 | G45: =AVERAGE(B45:F45) -> 0.0031251575 | H45: =_xlfn.RANK.EQ(G45,G41:G46,1) -> 1
...

Sheet NVIDIA
A1: NVIDIA | AP1: by Geetanjali Jorige
A3: INCOME STATEMENT (GAAP)
A4: Reporting Date | B4: Jan 28, 2024 | C4: Jan 29, 2023 | D4: Jan 30, 2022 | E4: Jan 31, 2021 | F4: Jan 26, 2020
A5: Item (M) | B5: 2024 | C5: 2023 | D5: 2022 | E5: 2021 | F5: 2020
A6: Total Revenue | B6: 60922 | C6: 26974 | D6: 26914 | E6: 16675 | F6: 10918
A7: Cost of Revenue | B7: 16621 | C7: 11618 | D7: 9439 | E7: 6279 | F7: 4150
A8: Gross Profit | B8: =B6-B7 -> 44301 | C8: =C6-C7 -> 15356 | D8: =D6-D7 -> 17475 | E8: =E6-E7 -> 10396 | F8: =F6-F7 -> 6768
A9: Total Operating Expenses | B9: =B47 -> 11329 | C9: =C47 -> 11132 | D9: =D47 -> 7434 | E9: =E47 -> 5864 | F9: =F47 -> 3922
A10: Operating Income (EBIT) | B10: =B8-B9 -> 32972 | C10: =C8-C9 -> 4224 | D10: =D8-D9 -> 10041 | E10: =E8-E9 -> 4532 | F10: =F8-F9 -> 2846
A11: Operating Margin (%) | B11: =B10/B6 -> 0.54121664 | C11: =C10/C6 -> 0.15659524 | D11: =D10/D6 -> 0.37307721 | E11: =E10/E6 -> 0.27178411 | F11: =F10/F6 -> 0.26067045
A12: Income Before Taxes | B12: 33818 | C12: 4181 | D12: 9941 | E12: 4409 | F12: 2970
A13: Income Tax Expense (Benefit) | B13: 4058 | C13: -187 | D13: 189 | E13: 77 | F13: 174
A14: Net Income | B14: 29760 | C14: 4368 | D14: 9752 | E14: 4332 | F14: 2796
A17: BALANCE SHEET
A18: Balance Sheet Item (M) | B18: 2024 | C18: 2023 | D18: 2022 | E18: 2021 | F18: 2020
A19: Cash & Equivalents | B19: 7280 | C19: 3389 | D19: 1990 | E19: 847 | F19: 10896
A20: Total Current Assets | B20: 44345 | C20: 23073 | D20: 28829 | E20: 16055 | F20: 13690
A21: Total Assets | B21: 65728 | C21: 41182 | D21: 44187 | E21: 28791 | F21: 17315
A22: Total Current Liabilities | B22: 10631 | C22: 6563 | D22: 3925 | E22: 3925 | F22: 1784
A23: Long-Term Debt | B23: 8459 | C23: 9703 | D23: 10946 | E23: 5964 | F23: 1991
A24: Total Liabilities | B24: 22750 | C24: 19081 | D24: 17575 | E24: 11898 | F24: 5111
A25: Total Shareholders' Equity | B25: 42978 | C25: 22101 | D25: 26612 | E25: 16893 | F25: 12204
A28: CASH FLOW
A29: Cash Flow/Investing (M) | B29: 2024 | C29: 2023 | D29: 2022 | E29: 2021 | F29: 2020
A30: Cash from Financial Activities | B30: -13633 | C30: -11617 | D30: 1865 | E30: 3804 | F30: -792
A31: Cash from Operating Activities (CFO) | B31: 28090 | C31: 5641 | D31: 9108 | E31: 5822 | F31: 4761
A32: Cash from Investing Activities | B32: -10566 | C32: 7375 | D32: -9830 | E32: -19675 | F32: 6145
A33: Free Cashflow | B33: =B31-ABS(B32) -> 17524 | C33: =C31-ABS(C32) -> -1734 | D33: =D31-ABS(D32) -> -722 | E33: =E31-ABS(E32) -> -13853 | F33: =F31-ABS(F32) -> -1384
A36: INVESTING ACTIVITIES
A37: Investing (M) | B37: 2024 | C37: 2023 | D37: 2022 | E37: 2021 | F37: 2020
A38: Purchases of PP&E & Intangibles (Capex/CFInv) | B38: -1069 | C38: -1833 | D38: -976 | E38: -1128 | F38: -489
A39: Acquisitions, net of cash acquired | B39: -83 | C39: -49 | D39: -263 | E39: -8524 | F39: -4
A42: OPERATIONAL EXPENSES BREAKDOWN
A43: Operating Expenses (M) | B43: 2024 | C43: 2023 | D43: 2022 | E43: 2021 | F43: 2020
A44: Research and development (R&D) | B44: 8675 | C44: 7339 | D44: 5268 | E44: 3924 | F44: 2829
A45: Selling, general and administrative (SG&A) | B45: 2654 | C45: 2440 | D45: 2166 | E45: 1940 | F45: 1093
A46: Acquisition Termination Cost | B46: 0 | C46: 1353 | D46: 0 | E46: 0 | F46: 0
A47: Total Operating Expenses | B47: =B44+B45+B46 -> 11329 | C47: =C44+C45+C46 -> 11132 | D47: =D44+D45+D46 -> 7434 | E47: =E44+E45+E46 -> 5864 | F47: =F44+F45+F46 -> 3922
A50: SEGMENT REVENUE DATA
A51: Segment Revenue (M) | B51: 2024 | C51: 2023 | D51: 2022 | E51: 2021 | F51: 2020
...

Sheet AMD
A1: ADVANCED MICRO DEVICES (AMD) INC | AE1: by Gurusharan Kannan
A3: INCOME STATEMENT (GAAP)
A4: Reporting date | B4: Dec 28, 2024 | C4: Dec 30, 2023 | D4: Dec 31, 2022 | E4: Dec 25, 2021 | F4: Dec 26, 2020 | Q4: A steadily growing revenue of AMD for the five years is observed which is supported by gradual increase in the sales cost. This means that AMD is doing really well in terms of quantity and quality and thus, its gross profit is getting higher. The highest revenue in 2023 is mainly attributed by the revenue coming from the company Xilinx, a major acquisition. In 2023 there was a little fluctuation but AMD managed to showcase a good revenue recovery in 2024.
A5: Items (In $ Millions) | B5: 2024 | C5: 2023 | D5: 2022 | E5: 2021 | F5: 2020
A6: Total Revenue (Sales) | B6: 25785 | C6: 22680 | D6: 23601 | E6: 16434 | F6: 9763
A7: Total Cost of Sales | B7: 13060 | C7: 12220 | D7: 12998 | E7: 8505 | F7: 5416
A8: Gross Profit | B8: =B6-B7 -> 12725 | C8: =C6-C7 -> 10460 | D8: =D6-D7 -> 10603 | E8: =E6-E7 -> 7929 | F8: =F6-F7 -> 4347
A9: Total Operating Expenses | B9: =B41 -> 10825 | C9: =C41 -> 10059 | D9: =D41 -> 9339 | E9: =E41 -> 4281 | F9: =F41 -> 2978
A10: Operating Profit | B10: =B8-B9 -> 1900 | C10: =C8-C9 -> 401 | D10: =D8-D9 -> 1264 | E10: =E8-E9 -> 3648 | F10: =F8-F9 -> 1369
A11: Other Income | B11: 181 | C11: 197 | D11: 8 | E11: 55 | F11: -47
A12: Interest expense | B12: -92 | C12: -106 | D12: -88 | E12: -34 | F12: -47 | Q12: Total operating expenses surged threefold from 2020 to 2024. The primary reason for the large increase in operating expenses is the Xilinx acquisition added with its overheads. The decline in 2023 reveals some stabilization and cost-cutting activities, but OpEx rose again in 2024 as AMD's strategic focus shifted to AI and innovation-centered, thus activating its heavy R&D spending. AMD's operating expenses grew by 263% in the period from 2020 to 2024. The company is gradually changing its position from a small player to a large, multi-segment player in the technology industry.
A13: Net Income | B13: 1641 | C13: 854 | D13: 1320 | E13: 3162 | F13: 2490
A14: Comprehensive Income | B14: 1582 | C14: 885 | D14: 1282 | E14: 3142 | F14: 2507
A16: Year-on-Year Change %
A17: Items | B17: 2024/23 | C17: 2023/22 | D17: 2022/21 | E17: 2021/20 | F17: 2020/19
A18: Total Revenue (Sales) | B18: =B6/C6-1 -> 0.13690476 | C18: =C6/D6-1 -> -0.03902377 | D18: =D6/E6-1 -> 0.43610807 | E18: =E6/F6-1 -> 0.68329407 | F18: =F6/6731-1 -> 0.45045313
A19: Total Cost of Sales | B19: =B7/C7-1 -> 0.068739771 | C19: =C7/D7-1 -> -0.059855362 | D19: =D7/E7-1 -> 0.52827748 | E19: =E7/F7-1 -> 0.57034712 | F19: =F7/3863-1 -> 0.40201916
A20: Total Operating Expenses | B20: =B9/C9-1 -> 0.076150711 | C20: =C9/D9-1 -> 0.077096049 | D20: =D9/E9-1 -> 1.1814996 | E20: =E9/F9-1 -> 0.43754197 | F20: =F9/2237-1 -> 0.33124721
A21: Gross Profit | B21: =B8/C8-1 -> 0.2165392 | C21: =C8/D8-1 -> -0.013486749 | D21: =D8/E8-1 -> 0.33724303 | E21: =E8/F8-1 -> 0.82401656 | F21: =F8/2868-1 -> 0.51569038
A22: Operating Profit (Loss) | B22: =B10/C10-1 -> 3.7381546 | C22: =C10/D10-1 -> -0.68275316 | D22: =D10/E10-1 -> -0.65350877 | E22: =E10/F10-1 -> 1.6647188 | F22: =F10/631-1 -> 1.1695721
A23: Net Income | B23: =B13/C13-1 -> 0.92154567 | C23: =C13/D13-1 -> -0.3530303 | D23: =D13/E13-1 -> -0.58254269 | E23: =E13/F13-1 -> 0.26987952 | F23: =F13/341-1 -> 6.3020528 | Q23: After 2022, operating expenses saw a dramatic increase. This was primarily due to major R&D investments, higher adminsitrative costs, and a very significant rise in the amortization costs associated with the Xilinx acquisition. The graph quite vividly indicates that the purchase had a profound effect on AMD’s cost structure, so to speak, the company became heavier but at the same time, it was ready for the long-term innovation and the expansion into new markets.
A25: Long term growth %
A26: Items | B26: 2024/20 | C26: 2023/20 | D26: 2022/20 | E26: 2021/20 | F26: 2020
A27: Total Revenue (Sales) | B27: =B6/F6-1 -> 1.6410939 | C27: =C6/F6-1 -> 1.3230564 | D27: =D6/F6-1 -> 1.4173922 | E27: =E6/F6-1 -> 0.68329407 | F27: =F6/F6-1 -> 0
A28: Total Cost of Sales | B28: =B7/F7-1 -> 1.4113737 | C28: =C7/F7-1 -> 1.2562777 | D28: =D7/F7-1 -> 1.3999261 | E28: =E7/F7-1 -> 0.57034712 | F28: =F7/F7-1 -> 0
A29: Total Operating Expenses | B29: =B9/F9-1 -> 2.6349899 | C29: =C9/F9-1 -> 2.3777703 | D29: =D9/F9-1 -> 2.1359973 | E29: =E9/F9-1 -> 0.43754197 | F29: =F8/F8-1 -> 0
A30: Gross Profit | B30: =B8/F8-1 -> 1.9273062 | C30: =C8/F8-1 -> 1.4062572 | D30: =D8/F8-1 -> 1.4391534 | E30: =E8/F8-1 -> 0.82401656 | F30: =F9/F9-1 -> 0
A31: Operating Profit (Loss) | B31: =B10/F10-1 -> 0.38787436 | C31: =C10/F10-1 -> -0.70708546 | D31: =D10/F10-1 -> -0.07669832 | E31: =E10/F10-1 -> 1.6647188 | F31: =F10/F10-1 -> 0
A32: Net Income | B32: =B13/F13-1 -> -0.34096386 | C32: =C13/F13-1 -> -0.65702811 | D32: =D13/F13-1 -> -0.46987952 | E32: =E13/F13-1 -> 0.26987952 | F32: =F11/F11-1 -> 0
Q33: Operating margins go up steadily until 2021, then they decline drastically in 2022 and 2023 and finally recover a little in 2024. The decline is closely related to the increase in operating costs caused by the Xilinx acquisition. Although sales are still good, the additional costs will impact AMD's profit negatively in the short term. The slight increase in 2024 indicates the firm is gradually taking in these costs.
A34: Operating Expenses
A35: Items (In $ Millions) | B35: 2024 | C35: 2023 | D35: 2022 | E35: 2021 | F35: 2020
A36: Research and development | B36: 6456 | C36: 5872 | D36: 5005 | E36: 2845 | F36: 1983
A37: Marketing, general and administrative | B37: 2783 | C37: 2352 | D37: 2336 | E37: 1448 | F37: 995
A38: Amortization of acquisition-related intangibles | B38: 1448 | C38: 1869 | D38: 2100 | E38: 0 | F38: 0
A39: Restructuring charges | B39: 186 | C39: - | D39: - | E39: 0 | F39: 0
A40: Licensing gain | B40: -48 | C40: -34 | D40: -102 | E40: -12 | F40: 0
A41: Total | B41: =SUM(B36:B40) -> 10825 | C41: =SUM(C36:C40) -> 10059 | D41: =SUM(D36:D40) -> 9339 | E41: =SUM(E36:E40) -> 4281 | F41: =SUM(F36:F40) -> 2978
A43: Segmented Revenue Data
A44: Segments (in $ millions) | B44: 2024 | C44: 2023 | D44: 2022 | E44: 2021 | F44: 2020 | Q44: Net profit margin during the year 2020-2021 was very high but suddenly falls starting from 2022. The main reasons for the decrease are the high amortization, increased R&D, and the market conditions. Margins do not go back to the same level as pre-acquisition phase even in 2024, hinting at the long-term financial effect of Xilinx. Nevertheless, the upward trend in recovery suggests better stability.
...

Sheet Qualcomm
A1: QUALCOMM | P1: by Manav Dharora
A2: Income Statement
A3: Reporting Date | B3: 28th Sept 2024 | C3: 24th Sept 2023 | D3: 25th Sept 2022 | E3: 26th Sept 2021 | F3: 27th Sept 2020
A4: Item | B4: 2024 | C4: 2023 | D4: 2022 | E4: 2021 | F4: 2020
A5: Total Revenues (Sales) | B5: 38962 | C5: 35820 | D5: 44200 | E5: 33566 | F5: 23531
A6: Total Cost of Revenue | B6: 17060 | C6: 15869 | D6: 18635 | E6: 14262 | F6: 9255
A7: Gross Profit | B7: 21902 | C7: 19951 | D7: 25565 | E7: 19304 | F7: 14276
A8: Total Operating Expenses | B8: =B34 -> 13358 | C8: =C34 -> 13110 | D8: =D34 -> 12526 | E8: =E34 -> 11097 | F8: =F34 -> 9442
A9: Operating Profit (Loss) (EBIT) | B9: =SUM(B7,-B8) -> 8544 | C9: =SUM(C7,-C8) -> 6841 | D9: =SUM(D7,-D8) -> 13039 | E9: =SUM(E7,-E8) -> 8207 | F9: =SUM(F7,-F8) -> 4834
A10: Operating Margin | B10: =B9/B5 -> 0.21929059 | C10: =C9/C5 -> 0.19098269 | D10: =D9/D5 -> 0.295 | E10: =E9/E5 -> 0.24450337 | F10: =F9/F5 -> 0.20543113
A11: Other Income (expense), net | B11: 962 | C11: 349 | D11: (372) | E11: 1044 | F11: 66
A12: Interest expense | B12: (697) | C12: (694) | D12: (490) | E12: (559) | F12: (602)
A13: Net Income | B13: 10142 | C13: 7232 | D13: 12936 | E13: 9043 | F13: 5198
A14: Comprehensive Income | B14: 10371 | C14: 7612 | D14: 12786 | E14: 8964 | F14: 5305
A15: Net Profit Margin | B15: 0.26 | C15: 0.2 | D15: 0.29 | E15: 0.27 | F15: 0.23
A17: Item | B17: 2024 | C17: 2023 | D17: 2022 | E17: 2021 | F17: 2020
A18: Total Revenue (In US millions) | B18: 38962 | C18: 35820 | D18: 44200 | E18: 33566 | F18: 23531
A19: Total Cost of Sales | B19: 17060 | C19: 15869 | D19: 18635 | E19: 14262 | F19: 9255
A21: Year-on-Year Change % | B21: 2024/23 | C21: 2023/22 | D21: 2022/21 | E21: 2021/20
A22: Total Revenues (Sales) | B22: =(B5-C5)/C5 -> 0.08771636 | C22: =(C5-D5)/D5 -> -0.18959276 | D22: =(D5-E5)/E5 -> 0.31680868 | E22: =(E5-F5)/F5 -> 0.42645871
A23: Total Cost of Sales | B23: =(B6-C6)/C6 -> 0.075051988 | C23: =(C6-D6)/D6 -> -0.14843037 | D23: =(D6-E6)/E6 -> 0.30661899 | E23: =(E6-F6)/F6 -> 0.54100486
A24: Total Operating Expenses | B24: =(B8-C8)/C8 -> 0.018916857 | C24: =(C8-D8)/D8 -> 0.046623024 | D24: =(D8-E8)/E8 -> 0.12877354 | E24: =(E8-F8)/F8 -> 0.17528066
A25: Gross Profit | B25: =(B7-C7)/C7 -> 0.097789584 | C25: =(C7-D7)/D7 -> -0.21959711 | D25: =(D7-E7)/E7 -> 0.32433692 | E25: =(E7-F7)/F7 -> 0.3521995
A26: Operating Profit (Loss) (EBIT) | B26: =(B9-C9)/C9 -> 0.24894021 | C26: =(C9-D9)/D9 -> -0.4753432 | D26: =(D9-E9)/E9 -> 0.58876569 | E26: =(E9-F9)/F9 -> 0.69776583
A27: Net Income | B27: =(B13-C13)/C13 -> 0.40237832 | C27: =(C13-D13)/D13 -> -0.44094001 | D27: =(D13-E13)/E13 -> 0.43049873 | E27: =(E13-F13)/F13 -> 0.73970758
A29: Operating Expenses
A30: Item | B30: 2024 | C30: 2023 | D30: 2022 | E30: 2021 | F30: 2020
A31: Research and development | B31: 8893 | C31: 8818 | D31: 8194 | E31: 7176 | F31: 5975
A32: Marketing, general and administrative | B32: 2759 | C32: 2483 | D32: 2570 | E32: 2339 | F32: 2074
A33: Depreciation and amortization expense | B33: 1706 | C33: 1809 | D33: 1762 | E33: 1582 | F33: 1393
A34: Total | B34: =SUM(B31:B33) -> 13358 | C34: =SUM(C31:C33) -> 13110 | D34: =SUM(D31:D33) -> 12526 | E34: =SUM(E31:E33) -> 11097 | F34: =SUM(F31:F33) -> 9442
A37: Investing Activities (CapEx)
A38: Item | B38: 2024 | C38: 2023 | D38: 2022 | E38: 2021 | F38: 2020
A39: Purchases of plant, property and equipment | B39: -1041 | C39: -1450 | D39: -2262 | E39: -1888 | F39: -1407
A40: Purchases of debt and equity marketable securities | B40: -5069 | C40: -668 | D40: -1414 | E40: -5907 | F40: -6213
A41: Proceeds from sales and maturities of debt and equity marketable securities | B41: 2677 | C41: 1566 | D41: 2622 | E41: 5555 | F41: 2399
A42: Acquisitions and other investments, net of cash acquired | B42: -254 | C42: -235 | D42: -4912 | E42: -1377 | F42: -185
A43: Proceeds from sales of property, plant and equipment | B43: 10 | C43: 127 | D43: 5 | E43: 3 | F43: -
A44: Proceeds from other investments | B44: 88 | C44: 20 | D44: 132 | E44: 320 | F44: 100
A45: Other items | B45: -36 | C45: 19 | D45: 41 | E45: -62 | F45: 43
...

Sheet ARM
A1: ARM | R1: by Gloria
A3: INCOME STATEMENT
A4: FISCAL YEAR END | B4: 31 March 2025 | C4: 31 March 2024 | D4: 31 March 2023 | E4: 31 March 2022 | F4: 31 March 2021
A5: Financial Metric | B5: FY2024 | C5: FY2023 | D5: FY2022 | E5: FY2021 | F5: FY2020
A7: Total Revenue | B7: 4007 | C7: 3233 | D7: 2679 | E7: 2703 | F7: 2027
A8: Net Income | B8: 792 | C8: 306 | D8: 524 | E8: 676 | F8: 544
A9: Cost of Revenue | B9: -121 | C9: -154 | D9: -106 | E9: -131 | F9: -145
A10: Gross Profit | B10: 3886 | C10: 3079 | D10: 2773 | E10: 2834 | F10: 1882
A11: Total Operating Expenses | B11: =B36 -> 3055 | C11: =C36 -> 2968 | D11: =D36 -> 1902 | E11: =E36 -> 1939 | F11: =F36 -> 1643
A12: Operating Income (EBIT) | B12: 831 | C12: 111 | D12: 671 | E12: 633 | F12: 239
A13: Operating Margin (%) | B13: =B12/B7 -> 0.20738707 | C13: =C12/C7 -> 0.034333436 | D13: =D12/D7 -> 0.25046659 | E13: =E12/E7 -> 0.23418424 | F13: =F12/F7 -> 0.11790824
A14: Income Before Taxes | B14: 720 | C14: 212 | D14: 671 | E14: 786 | F14: 697
A15: Income Tax Expense (Benefit) | B15: 72 | C15: 94 | D15: -147 | E15: -110 | F15: -153
A18: CASH FLOW
A19: Financial Metric | B19: FY2024 | C19: FY2023 | D19: FY2022 | E19: FY2021 | F19: FY2020
A21: FREE CASH FLOW | B21: =B24+B23 -> 362 | C21: =C24+C23 -> 574 | D21: =D24+D23 -> 601 | E21: =E24+E23 -> -161 | F21: =F24+F23 -> 893
A22: Net cash provided by (used for) financing activities | B22: -202 | C22: -208 | D22: -42 | E22: -32 | F22: -789
A23: Net cash provided by (used for) investing activities | B23: -35 | C23: -516 | D23: -138 | E23: -619 | F23: -340
A24: Net cash provided by (used for) operating activities | B24: 397 | C24: 1090 | D24: 739 | E24: 458 | F24: 1233
A25: Effect of foreign exchange rate changes on cash and cash equivalents | B25: 2 | C25: 3 | D25: -9 | E25: -17 | F25: 1
A26: Net increase (decrease) in cash and cash equivalents | B26: 162 | C26: 369 | D26: 550 | E26: -210 | F26: 105
A29: OPERATING EXPENSES
A30: Financial Metric | B30: FY2024 | C30: FY2023 | D30: FY2022 | E30: FY2021 | F30: FY2020
A32: Research and Development | B32: 2071 | C32: 1979 | D32: 1133 | E32: 995 | F32: 814
A33: Impairment Of Long Live Assets | E33: 21 | F33: 3
A34: Selling,general and administrative | B34: 984 | C34: 983 | D34: 762 | E34: 897 | F34: 826
A35: Disposal , restructuring and other operating expense | C35: 6 | D35: 7 | E35: 26
A36: Operating Expense | B36: =SUM(B32:B35) -> 3055 | C36: =SUM(C32:C35) -> 2968 | D36: =SUM(D32:D35) -> 1902 | E36: =SUM(E32:E35) -> 1939 | F36: =SUM(F32:F35) -> 1643
A40: INVESTING ACTIVITIES
A41: Financial Metric | B41: FY2024 | C41: FY2023 | D41: FY2022 | E41: FY2021 | F41: FY2020
A43: Purchase of plant ,property and equipment | B43: 219 | C43: 74 | D43: 34 | E43: -103 | F43: -142
A44: Purchase of intangible assets | B44: 20 | C44: 69 | D44: 78 | E44: -88 | F44: -38
A45: Investment In Associates | C45: -2 | D45: 0 | E45: -4 | F45: -8
A46: Purchase Of trading investments | B46: 57 | C46: -11 | D46: 6 | E46: -45 | F46: -47
A47: Payments for financial assets | D47: -29 | E47: -2
A48: TOTAL | B48: =SUM(B43,B45,B44,B46,B47) -> 296 | C48: =SUM(C43,C45,C44,C46,C47) -> 130 | D48: =SUM(D43,D45,D44,D46,D47) -> 89 | E48: =SUM(E43,E45,E44,E46,E47) -> -242 | F48: =SUM(F43,F45,F44,F46,F47) -> -235
A50: Financial Metric | B50: 2025-24 | C50: 2024-23 | D50: 2023-22 | E50: 2022-21 | F50: 2021-20
A51: Gross Margin | B51: =B10/B7 -> 0.96980285 | C51: =C10/C7 -> 0.95236622 | D51: =D10/D7 -> 1.0350877 | E51: =E10/E7 -> 1.0484647 | F51: =F10/F7 -> 0.92846571
A52: Operating Margin | B52: =B12/B7 -> 0.20738707 | C52: =C12/C7 -> 0.034333436 | D52: =D12/D7 -> 0.25046659 | E52: =E12/E7 -> 0.23418424 | F52: =F12/F7 -> 0.11790824
A53: Profit Margin | B53: =B8/B7 -> 0.19765411 | C53: =C8/C7 -> 0.094648933 | D53: =D8/D7 -> 0.19559537 | E53: =E8/E7 -> 0.25009249 | F53: =F8/F7 -> 0.26837691
...

Sheet TSMC
A1: TSMC | G1: by Ting Hsuan Huang
A2: INCOME STATEMENT
A3: <IFRS> (Unit: NT$ billion) | B3: FY2024 | C3: FY2023 | D3: FY2022 | E3: FY2021 | F3: FY2020
A4: Revenue (Total Sales) | B4: 2894.3 | C4: 2161.7 | D4: 2263.9 | E4: 1587.4 | F4: 1339.3
A5: Cost of sales | B5: 1270 | C5: 986.6 | D5: 915.5 | E5: 767.9 | F5: 628.1
A6: Gross profit | B6: 1624.3 | C6: 1175.1 | D6: 1348.4 | E6: 819.5 | F6: 711.1
A7: Operating profit | B7: 1322.1 | C7: 921.5 | D7: 1121.3 | E7: 650 | F7: 566.8
A8: EBIDTA | B8: 1594 | C8: 1224 | D8: 1389 | E8: 948 | F8: 838
A9: Profit before income taxes | B9: 1405.8 | C9: 979 | D9: 1144 | E9: 663.1 | F9: 585
A10: Net Income | B10: 1016 | C10: 825 | D10: 1016 | E10: 597 | F10: 517
B13: FY2024 | C13: FY2023 | D13: FY2022 | E13: FY2021 | F13: FY2020
A14: Operating Margin | B14: =B7/B4 -> 0.45679439 | C14: =C7/C4 -> 0.42628487 | D14: =D7/D4 -> 0.49529573 | E14: =E7/E4 -> 0.40947461 | F14: =F7/F4 -> 0.42320615
A15: Gross Profit Margin | B15: =B6/B4 -> 0.56120651 | C15: =C6/C4 -> 0.54359994 | D15: =D6/D4 -> 0.59560935 | E15: =E6/E4 -> 0.51625299 | F15: =F6/F4 -> 0.530949
A16: Net Profit Margin | B16: =B10/B4 -> 0.35103479 | C16: =C10/C4 -> 0.38164408 | D16: =D10/D4 -> 0.44878307 | E16: =E10/E4 -> 0.37608668 | F16: =F10/F4 -> 0.38602255
A19: Year-on-Year (%) Change | B19: FY2024-23 | C19: FY2023-22 | D19: FY2022-21 | E19: FY2021-20
A20: Revenue | B20: =B4/C4-1 -> 0.33889994 | C20: =C4/D4-1 -> -0.045143337 | D20: =D4/E4-1 -> 0.42616858 | E20: =E4/F4-1 -> 0.18524602
A21: Cost of sales | B21: =B5/C5-1 -> 0.28724914 | C21: =C5/D5-1 -> 0.07766248 | D21: =D5/E5-1 -> 0.19221253 | E21: =E5/F5-1 -> 0.22257602
A22: Gross profit | B22: =B6/C6-1 -> 0.38226534 | C22: =C6/D6-1 -> -0.12852269 | D22: =D6/E6-1 -> 0.64539353 | E22: =E6/F6-1 -> 0.15243988
A23: Operating profit | B23: =B7/C7-1 -> 0.43472599 | C23: =C7/D7-1 -> -0.17818603 | D23: =D7/E7-1 -> 0.72507692 | E23: =E7/F7-1 -> 0.14678899
A24: Profit before income taxes | B24: =B9/C9-1 -> 0.43595506 | C24: =C9/D9-1 -> -0.14423077 | D24: =D9/E9-1 -> 0.72522998 | E24: =E9/F9-1 -> 0.13350427
A27: Operating Expenses | B27: FY2024 | C27: FY2023 | D27: FY2022 | E27: FY2021 | F27: FY2020
A28: R&D ( research and development expenses) | B28: 198.9 | C28: 179.6 | D28: 163.9 | E28: 115.5 | F28: 97.1
A29: G&A ( general and administrative expenses) | B29: 54.9 | C29: 46.8 | D29: 41.5 | E29: 33.3 | F29: 28.4
A30: Other operating income (loss), net | B30: -1.2 | C30: 0.2 | D30: -0.4 | E30: -0.3 | F30: -0.2
A31: Total Operating Expenses | B31: =SUM(B28:B30) -> 252.6 | C31: =SUM(C28:C30) -> 226.6 | D31: =SUM(D28:D30) -> 205 | E31: =SUM(E28:E30) -> 148.5 | F31: =SUM(F28:F30) -> 125.3
A34: Investing | B34: FY2024 | C34: FY2023 | D34: FY2022 | E34: FY2021 | F34: FY2020
A35: Property & equipment | B35: -635.9 | C35: -545.7 | D35: -450.9 | E35: -301.1 | F35: -294.1
A36: Intangible assets | B36: -6.1 | C36: -6 | D36: -5.7 | E36: -6.6 | F36: -5
A37: Other | B37: -47.6 | C37: -33.2 | D37: -27.4 | E37: -24.2 | F37: -49.7
A38: Total | B38: =SUM(B35:B37) -> -689.6 | C38: =SUM(C35:C37) -> -584.9 | D38: =SUM(D35:D37) -> -484 | E38: =SUM(E35:E37) -> -331.9 | F38: =SUM(F35:F37) -> -348.8
A40: Cash Flow Summary | B40: FY2024 | C40: FY2023 | D40: FY2022 | E40: FY2021 | F40: FY2020
A41: Cash Flow from Operating Activities (CFO) | B41: 1826.2 | C41: 1242 | D41: 1610.6 | E41: 1112.2 | F41: 822.7
A42: Cash Flow from Investing Activities (CFInv) | B42: -1014.9 | C42: -906.1 | D42: -1190.9 | E42: -836.4 | F42: -505.8
A43: Cash used in Financing Activities（CFF） | B43: -1999.4 | C43: -2102.8 | D43: -3631.2 | E43: -2038.5 | F43: -1840.2
A44: Free Cash Flow (FCF = CFO - CFInv) | B44: =B41-ABS(B42) -> 811.3 | C44: =C41-ABS(C42) -> 335.9 | D44: =D41-ABS(D42) -> 419.7 | E44: =E41-ABS(E42) -> 275.8 | F44: =F41-ABS(F42) -> 316.9
A47: Segmentation | B47: 2024 (USD mn) | C47: 2023 (USD mn) | D47: 2022 (USD mn) | E47: 2021 (USD mn) | F47: 2020 (USD mn)
A48: High Performance Computing | B48: 45502.2 | C48: 30100 | D48: 31283 | E48: 20979 | F48: 15015
A49: Smartphone | B49: 31227 | C49: 26600 | D49: 29757 | E49: 24948 | F49: 21840
A50: Internet of Things | B50: 5353.2 | C50: 5600 | D50: 6867 | E50: 4536 | F50: 3640
A51: Automotive | B51: 4461 | C51: 4200 | D51: 3815 | E51: 2268 | F51: 1365
...

Sheet Intel
A1: INTEL | G1: by Alperen Onal
A3: Income Statement
A4: Financial Metrics | B4: 2024 | C4: 2023 | D4: 2022 | E4: 2021 | F4: 2020
A5: Total Revenues (Sales) | B5: 53101 | C5: 54228 | D5: 63054 | E5: 79024 | F5: 77867
A6: Total Cost of Sales | B6: 34877 | C6: 31282 | D6: 34608 | E6: 35209 | F6: 34255
A7: Gross Profit | B7: 18224 | C7: 22946 | D7: 28446 | E7: 43815 | F7: 43612
A8: Gross Profit Margin | B8: 0.34 | C8: 0.42 | D8: 0.45 | E8: 0.55 | F8: 0.56
A9: Total Operating Expenses | B9: 22053 | C9: 21680 | D9: 24530 | E9: 21733 | F9: 19736
A10: Operating Profit | B10: -3829 | C10: 1266 | D10: 3916 | E10: 22082 | F10: 23876
A11: Operating Margin | B11: -0.07 | C11: 0.02 | D11: 0.06 | E11: 0.28 | F11: 0.31
A12: Other Income | B12: -1100 | C12: 306 | D12: 420 | E12: 263 | F12: 214
A13: Interest expense | B13: -900 | C13: -700 | D13: -500 | E13: -400 | F13: -400
A14: Net Income | B14: -18756 | C14: 1689 | D14: 8014 | E14: 19868 | F14: 20899
A15: Comprehensive Income | B15: -18900 | C15: 1700 | D15: 8100 | E15: 19950 | F15: 21000
A16: Net Profit Margin | B16: -0.35 | C16: 0.03 | D16: 0.13 | E16: 0.25 | F16: 0.27
A18: Items (In $ Millions) | B18: 2024 | C18: 2023 | D18: 2022 | E18: 2021 | F18: 2020 | G18: 2019
A19: Total Revenue (In US millions) | B19: 53101 | C19: 54228 | D19: 63054 | E19: 79024 | F19: 77867 | G19: 71965
A20: Total Cost of Sales | B20: 34877 | C20: 31282 | D20: 34608 | E20: 35209 | F20: 34255 | G20: 30186
A22: Year-on-Year Change % | B22: 2024/23 | C22: 2023/22 | D22: 2022/21 | E22: 2021/20 | F22: 2020/19
A23: Total Revenues (Sales) | B23: =B19/C19-1 -> -0.020782622 | C23: =C19/D19-1 -> -0.13997526 | D23: =D19/E19-1 -> -0.2020905 | E23: =E19/F19-1 -> 0.014858669 | F23: =F19/G19-1 -> 0.082012089
A24: Total Cost of Sales | B24: =B20/C20-1 -> 0.11492232 | C24: =C20/D20-1 -> -0.096104947 | D24: =D20/E20-1 -> -0.017069499 | E24: =E20/F20-1 -> 0.027849949 | F24: =F20/G20-1 -> 0.13479759
A25: Total Operating Expenses | B25: =B9/C9-1 -> 0.017204797 | C25: =C9/D9-1 -> -0.11618426 | D25: =D9/E9-1 -> 0.12869829 | E25: =E9/F9-1 -> 0.10118565 | F25: =F9/2237-1 -> 7.8225302
A26: Gross Profit | B26: =B7/C7-1 -> -0.2057875 | C26: =C7/D7-1 -> -0.1933488 | D26: =D7/E7-1 -> -0.35077028 | E26: =E7/F7-1 -> 0.0046546822 | F26: =F7/2868-1 -> 14.206416
A27: Operating Profit (Loss) | B27: =B10/C10-1 -> -4.0244866 | C27: =C10/D10-1 -> -0.67671093 | D27: =D10/E10-1 -> -0.82266099 | E27: =E10/F10-1 -> -0.075138214 | F27: =F10/631-1 -> 36.838352
A28: Net Income | B28: =B14/C14-1 -> -12.104796 | C28: =C14/D14-1 -> -0.78924382 | D28: =D14/E14-1 -> -0.59663781 | E28: =E14/F14-1 -> -0.049332504 | F28: =F14/341-1 -> 60.28739
A30: Operating Expenses
A31: Items (In $ Millions) | B31: 2024 | C31: 2023 | D31: 2022 | E31: 2021 | F31: 2020
A32: Research and development | B32: 16546 | C32: 16046 | D32: 17528 | E32: 15190 | F32: 13556
A33: Marketing, general and administrative | B33: 5507 | C33: 5634 | D33: 7002 | E33: 6543 | F33: 6180
A34: Amortization of acquisition-related intangibles | B34: 300 | C34: 350 | D34: 400 | E34: - | F34: -
A35: Restructuring charges | B35: 100 | C35: -50 | D35: 150 | E35: 20 | F35: -
A36: Licensing gain | B36: - | C36: - | D36: 100 | E36: - | F36: -
A38: Investing Activities (CapEx)
A39: Items (In $ Millions) | B39: 2024 | C39: 2023 | D39: 2022 | E39: 2021 | F39: 2020
A40: Purchases of property and equipment | B40: -23944 | C40: -25750 | D40: -25050 | E40: -20329 | F40: -14260
A41: Purchases and proceeds related to short-term investments | B41: -1700 | C41: -1500 | D41: -1800 | E41: -1200 | F41: -800
A42: Acquisitions, net of cash acquired | B42: -1500 | C42: -400 | D42: -1700 | E42: -900 | F42: -300
A43: Proceeds from divestitures / IPO / asset sales | B43: 861 | C43: -353 | D43: 7000 | E43: - | F43: -
A44: Other | B44: -500 | C44: -100 | D44: -200 | E44: -150 | F44: -100
A46: Free Cash Flow
...
